Workbook

Sheet Bedrock_PLG
A1: User_Code | B1: GEOL_MAPPING_UNIT_Display | C1: GEOL_MAPPING_UNIT | D1: TECTO_Display | E1: TECTO | F1: LITSTRAT_FORMATION_BANK_Display | G1: CHRONO_TOP_Display | H1: CHRONO_BASE_Display | I1: LITHO_MAIN_Display | J1: LITHO_SEC_Display | K1: LITHO_TER_Display
A2: BEDROCK_001 | C2: =IF(B2="","",VALUE(LEFT(B2,FIND(":",B2)-1))) | E2: =IF(D2="","",VALUE(LEFT(D2,FIND(":",D2)-1))) | F2: =IF(C2="","",IFERROR(INDEX(Ref_LithoStratFormation!$C:$C,MATCH(VLOOKUP(C2,Ref_GMU_Attributes!$A:$B,COLUMN(B:$B),FALSE),Ref_LithoStratFormation!$A:$A,0)),"")) | G2: =IF(C2="","",IFERROR(INDEX(Ref_Chrono!$C:$C,MATCH(VLOOKUP(C2,Ref_GMU_Attributes!$A:$C,COLUMN(C:$C),FALSE),Ref_Chrono!$A:$A,0)),"")) | H2: =IF(C2="","",IFERROR(INDEX(Ref_Chrono!$C:$C,MATCH(VLOOKUP(C2,Ref_GMU_Attributes!$A:$D,COLUMN(D:$D),FALSE),Ref_Chrono!$A:$A,0)),"")) | I2: =IF(C2="","",IFERROR(INDEX(Ref_Litho!$C:$C,MATCH(VLOOKUP(C2,Ref_GMU_Attributes!$A:$E,COLUMN(E:$E),FALSE),Ref_Litho!$A:$A,0)),"")) | J2: =IF(C2="","",IFERROR(INDEX(Ref_Litho!$C:$C,MATCH(VLOOKUP(C2,Ref_GMU_Attributes!$A:$F,COLUMN(F:$F),FALSE),Ref_Litho!$A:$A,0)),"")) | K2: =IF(C2="","",IFERROR(INDEX(Ref_Litho!$C:$C,MATCH(VLOOKUP(C2,Ref_GMU_Attributes!$A:$G,COLUMN(G:$G),FALSE),Ref_Litho!$A:$A,0)),""))
A3: BEDROCK_002 | C3: =IF(B3="","",VALUE(LEFT(B3,FIND(":",B3)-1))) | E3: =IF(D3="","",VALUE(LEFT(D3,FIND(":",D3)-1))) | F3: =IF(C3="","",IFERROR(INDEX(Ref_LithoStratFormation!$C:$C,MATCH(VLOOKUP(C3,Ref_GMU_Attributes!$A:$B,COLUMN(B:$B),FALSE),Ref_LithoStratFormation!$A:$A,0)),"")) | G3: =IF(C3="","",IFERROR(INDEX(Ref_Chrono!$C:$C,MATCH(VLOOKUP(C3,Ref_GMU_Attributes!$A:$C,COLUMN(C:$C),FALSE),Ref_Chrono!$A:$A,0)),"")) | H3: =IF(C3="","",IFERROR(INDEX(Ref_Chrono!$C:$C,MATCH(VLOOKUP(C3,Ref_GMU_Attributes!$A:$D,COLUMN(D:$D),FALSE),Ref_Chrono!$A:$A,0)),"")) | I3: =IF(C3="","",IFERROR(INDEX(Ref_Litho!$C:$C,MATCH(VLOOKUP(C3,Ref_GMU_Attributes!$A:$E,COLUMN(E:$E),FALSE),Ref_Litho!$A:$A,0)),"")) | J3: =IF(C3="","",IFERROR(INDEX(Ref_Litho!$C:$C,MATCH(VLOOKUP(C3,Ref_GMU_Attributes!$A:$F,COLUMN(F:$F),FALSE),Ref_Litho!$A:$A,0)),"")) | K3: =IF(C3="","",IFERROR(INDEX(Ref_Litho!$C:$C,MATCH(VLOOKUP(C3,Ref_GMU_Attributes!$A:$G,COLUMN(G:$G),FALSE),Ref_Litho!$A:$A,0)),""))
C4: =IF(B4="","",VALUE(LEFT(B4,FIND(":",B4)-1))) | E4: =IF(D4="","",VALUE(LEFT(D4,FIND(":",D4)-1))) | F4: =IF(C4="","",IFERROR(INDEX(Ref_LithoStratFormation!$C:$C,MATCH(VLOOKUP(C4,Ref_GMU_Attributes!$A:$B,COLUMN(B:$B),FALSE),Ref_LithoStratFormation!$A:$A,0)),"")) | G4: =IF(C4="","",IFERROR(INDEX(Ref_Chrono!$C:$C,MATCH(VLOOKUP(C4,Ref_GMU_Attributes!$A:$C,COLUMN(C:$C),FALSE),Ref_Chrono!$A:$A,0)),"")) | H4: =IF(C4="","",IFERROR(INDEX(Ref_Chrono!$C:$C,MATCH(VLOOKUP(C4,Ref_GMU_Attributes!$A:$D,COLUMN(D:$D),FALSE),Ref_Chrono!$A:$A,0)),"")) | I4: =IF(C4="","",IFERROR(INDEX(Ref_Litho!$C:$C,MATCH(VLOOKUP(C4,Ref_GMU_Attributes!$A:$E,COLUMN(E:$E),FALSE),Ref_Litho!$A:$A,0)),"")) | J4: =IF(C4="","",IFERROR(INDEX(Ref_Litho!$C:$C,MATCH(VLOOKUP(C4,Ref_GMU_Attributes!$A:$F,COLUMN(F:$F),FALSE),Ref_Litho!$A:$A,0)),"")) | K4: =IF(C4="","",IFERROR(INDEX(Ref_Litho!$C:$C,MATCH(VLOOKUP(C4,Ref_GMU_Attributes!$A:$G,COLUMN(G:$G),FALSE),Ref_Litho!$A:$A,0)),""))
C5: =IF(B5="","",VALUE(LEFT(B5,FIND(":",B5)-1))) | E5: =IF(D5="","",VALUE(LEFT(D5,FIND(":",D5)-1))) | F5: =IF(C5="","",IFERROR(INDEX(Ref_LithoStratFormation!$C:$C,MATCH(VLOOKUP(C5,Ref_GMU_Attributes!$A:$B,COLUMN(B:$B),FALSE),Ref_LithoStratFormation!$A:$A,0)),"")) | G5: =IF(C5="","",IFERROR(INDEX(Ref_Chrono!$C:$C,MATCH(VLOOKUP(C5,Ref_GMU_Attributes!$A:$C,COLUMN(C:$C),FALSE),Ref_Chrono!$A:$A,0)),"")) | H5: =IF(C5="","",IFERROR(INDEX(Ref_Chrono!$C:$C,MATCH(VLOOKUP(C5,Ref_GMU_Attributes!$A:$D,COLUMN(D:$D),FALSE),Ref_Chrono!$A:$A,0)),"")) | I5: =IF(C5="","",IFERROR(INDEX(Ref_Litho!$C:$C,MATCH(VLOOKUP(C5,Ref_GMU_Attributes!$A:$E,COLUMN(E:$E),FALSE),Ref_Litho!$A:$A,0)),"")) | J5: =IF(C5="","",IFERROR(INDEX(Ref_Litho!$C:$C,MATCH(VLOOKUP(C5,Ref_GMU_Attributes!$A:$F,COLUMN(F:$F),FALSE),Ref_Litho!$A:$A,0)),"")) | K5: =IF(C5="","",IFERROR(INDEX(Ref_Litho!$C:$C,MATCH(VLOOKUP(C5,Ref_GMU_Attributes!$A:$G,COLUMN(G:$G),FALSE),Ref_Litho!$A:$A,0)),""))
C6: =IF(B6="","",VALUE(LEFT(B6,FIND(":",B6)-1))) | E6: =IF(D6="","",VALUE(LEFT(D6,FIND(":",D6)-1))) | F6: =IF(C6="","",IFERROR(INDEX(Ref_LithoStratFormation!$C:$C,MATCH(VLOOKUP(C6,Ref_GMU_Attributes!$A:$B,COLUMN(B:$B),FALSE),Ref_LithoStratFormation!$A:$A,0)),"")) | G6: =IF(C6="","",IFERROR(INDEX(Ref_Chrono!$C:$C,MATCH(VLOOKUP(C6,Ref_GMU_Attributes!$A:$C,COLUMN(C:$C),FALSE),Ref_Chrono!$A:$A,0)),"")) | H6: =IF(C6="","",IFERROR(INDEX(Ref_Chrono!$C:$C,MATCH(VLOOKUP(C6,Ref_GMU_Attributes!$A:$D,COLUMN(D:$D),FALSE),Ref_Chrono!$A:$A,0)),"")) | I6: =IF(C6="","",IFERROR(INDEX(Ref_Litho!$C:$C,MATCH(VLOOKUP(C6,Ref_GMU_Attributes!$A:$E,COLUMN(E:$E),FALSE),Ref_Litho!$A:$A,0)),"")) | J6: =IF(C6="","",IFERROR(INDEX(Ref_Litho!$C:$C,MATCH(VLOOKUP(C6,Ref_GMU_Attributes!$A:$F,COLUMN(F:$F),FALSE),Ref_Litho!$A:$A,0)),"")) | K6: =IF(C6="","",IFERROR(INDEX(Ref_Litho!$C:$C,MATCH(VLOOKUP(C6,Ref_GMU_Attributes!$A:$G,COLUMN(G:$G),FALSE),Ref_Litho!$A:$A,0)),""))
C7: =IF(B7="","",VALUE(LEFT(B7,FIND(":",B7)-1))) | E7: =IF(D7="","",VALUE(LEFT(D7,FIND(":",D7)-1))) | F7: =IF(C7="","",IFERROR(INDEX(Ref_LithoStratFormation!$C:$C,MATCH(VLOOKUP(C7,Ref_GMU_Attributes!$A:$B,COLUMN(B:$B),FALSE),Ref_LithoStratFormation!$A:$A,0)),"")) | G7: =IF(C7="","",IFERROR(INDEX(Ref_Chrono!$C:$C,MATCH(VLOOKUP(C7,Ref_GMU_Attributes!$A:$C,COLUMN(C:$C),FALSE),Ref_Chrono!$A:$A,0)),"")) | H7: =IF(C7="","",IFERROR(INDEX(Ref_Chrono!$C:$C,MATCH(VLOOKUP(C7,Ref_GMU_Attributes!$A:$D,COLUMN(D:$D),FALSE),Ref_Chrono!$A:$A,0)),"")) | I7: =IF(C7="","",IFERROR(INDEX(Ref_Litho!$C:$C,MATCH(VLOOKUP(C7,Ref_GMU_Attributes!$A:$E,COLUMN(E:$E),FALSE),Ref_Litho!$A:$A,0)),"")) | J7: =IF(C7="","",IFERROR(INDEX(Ref_Litho!$C:$C,MATCH(VLOOKUP(C7,Ref_GMU_Attributes!$A:$F,COLUMN(F:$F),FALSE),Ref_Litho!$A:$A,0)),"")) | K7: =IF(C7="","",IFERROR(INDEX(Ref_Litho!$C:$C,MATCH(VLOOKUP(C7,Ref_GMU_Attributes!$A:$G,COLUMN(G:$G),FALSE),Ref_Litho!$A:$A,0)),""))
C8: =IF(B8="","",VALUE(LEFT(B8,FIND(":",B8)-1))) | E8: =IF(D8="","",VALUE(LEFT(D8,FIND(":",D8)-1))) | F8: =IF(C8="","",IFERROR(INDEX(Ref_LithoStratFormation!$C:$C,MATCH(VLOOKUP(C8,Ref_GMU_Attributes!$A:$B,COLUMN(B:$B),FALSE),Ref_LithoStratFormation!$A:$A,0)),"")) | G8: =IF(C8="","",IFERROR(INDEX(Ref_Chrono!$C:$C,MATCH(VLOOKUP(C8,Ref_GMU_Attributes!$A:$C,COLUMN(C:$C),FALSE),Ref_Chrono!$A:$A,0)),"")) | H8: =IF(C8="","",IFERROR(INDEX(Ref_Chrono!$C:$C,MATCH(VLOOKUP(C8,Ref_GMU_Attributes!$A:$D,COLUMN(D:$D),FALSE),Ref_Chrono!$A:$A,0)),"")) | I8: =IF(C8="","",IFERROR(INDEX(Ref_Litho!$C:$C,MATCH(VLOOKUP(C8,Ref_GMU_Attributes!$A:$E,COLUMN(E:$E),FALSE),Ref_Litho!$A:$A,0)),"")) | J8: =IF(C8="","",IFERROR(INDEX(Ref_Litho!$C:$C,MATCH(VLOOKUP(C8,Ref_GMU_Attributes!$A:$F,COLUMN(F:$F),FALSE),Ref_Litho!$A:$A,0)),"")) | K8: =IF(C8="","",IFERROR(INDEX(Ref_Litho!$C:$C,MATCH(VLOOKUP(C8,Ref_GMU_Attributes!$A:$G,COLUMN(G:$G),FALSE),Ref_Litho!$A:$A,0)),""))
C9: =IF(B9="","",VALUE(LEFT(B9,FIND(":",B9)-1))) | E9: =IF(D9="","",VALUE(LEFT(D9,FIND(":",D9)-1))) | F9: =IF(C9="","",IFERROR(INDEX(Ref_LithoStratFormation!$C:$C,MATCH(VLOOKUP(C9,Ref_GMU_Attributes!$A:$B,COLUMN(B:$B),FALSE),Ref_LithoStratFormation!$A:$A,0)),"")) | G9: =IF(C9="","",IFERROR(INDEX(Ref_Chrono!$C:$C,MATCH(VLOOKUP(C9,Ref_GMU_Attributes!$A:$C,COLUMN(C:$C),FALSE),Ref_Chrono!$A:$A,0)),"")) | H9: =IF(C9="","",IFERROR(INDEX(Ref_Chrono!$C:$C,MATCH(VLOOKUP(C9,Ref_GMU_Attributes!$A:$D,COLUMN(D:$D),FALSE),Ref_Chrono!$A:$A,0)),"")) | I9: =IF(C9="","",IFERROR(INDEX(Ref_Litho!$C:$C,MATCH(VLOOKUP(C9,Ref_GMU_Attributes!$A:$E,COLUMN(E:$E),FALSE),Ref_Litho!$A:$A,0)),"")) | J9: =IF(C9="","",IFERROR(INDEX(Ref_Litho!$C:$C,MATCH(VLOOKUP(C9,Ref_GMU_Attributes!$A:$F,COLUMN(F:$F),FALSE),Ref_Litho!$A:$A,0)),"")) | K9: =IF(C9="","",IFERROR(INDEX(Ref_Litho!$C:$C,MATCH(VLOOKUP(C9,Ref_GMU_Attributes!$A:$G,COLUMN(G:$G),FALSE),Ref_Litho!$A:$A,0)),""))
C10: =IF(B10="","",VALUE(LEFT(B10,FIND(":",B10)-1))) | E10: =IF(D10="","",VALUE(LEFT(D10,FIND(":",D10)-1))) | F10: =IF(C10="","",IFERROR(INDEX(Ref_LithoStratFormation!$C:$C,MATCH(VLOOKUP(C10,Ref_GMU_Attributes!$A:$B,COLUMN(B:$B),FALSE),Ref_LithoStratFormation!$A:$A,0)),"")) | G10: =IF(C10="","",IFERROR(INDEX(Ref_Chrono!$C:$C,MATCH(VLOOKUP(C10,Ref_GMU_Attributes!$A:$C,COLUMN(C:$C),FALSE),Ref_Chrono!$A:$A,0)),"")) | H10: =IF(C10="","",IFERROR(INDEX(Ref_Chrono!$C:$C,MATCH(VLOOKUP(C10,Ref_GMU_Attributes!$A:$D,COLUMN(D:$D),FALSE),Ref_Chrono!$A:$A,0)),"")) | I10: =IF(C10="","",IFERROR(INDEX(Ref_Litho!$C:$C,MATCH(VLOOKUP(C10,Ref_GMU_Attributes!$A:$E,COLUMN(E:$E),FALSE),Ref_Litho!$A:$A,0)),"")) | J10: =IF(C10="","",IFERROR(INDEX(Ref_Litho!$C:$C,MATCH(VLOOKUP(C10,Ref_GMU_Attributes!$A:$F,COLUMN(F:$F),FALSE),Ref_Litho!$A:$A,0)),"")) | K10: =IF(C10="","",IFERROR(INDEX(Ref_Litho!$C:$C,MATCH(VLOOKUP(C10,Ref_GMU_Attributes!$A:$G,COLUMN(G:$G),FALSE),Ref_Litho!$A:$A,0)),""))
C11: =IF(B11="","",VALUE(LEFT(B11,FIND(":",B11)-1))) | E11: =IF(D11="","",VALUE(LEFT(D11,FIND(":",D11)-1))) | F11: =IF(C11="","",IFERROR(INDEX(Ref_LithoStratFormation!$C:$C,MATCH(VLOOKUP(C11,Ref_GMU_Attributes!$A:$B,COLUMN(B:$B),FALSE),Ref_LithoStratFormation!$A:$A,0)),"")) | G11: =IF(C11="","",IFERROR(INDEX(Ref_Chrono!$C:$C,MATCH(VLOOKUP(C11,Ref_GMU_Attributes!$A:$C,COLUMN(C:$C),FALSE),Ref_Chrono!$A:$A,0)),"")) | H11: =IF(C11="","",IFERROR(INDEX(Ref_Chrono!$C:$C,MATCH(VLOOKUP(C11,Ref_GMU_Attributes!$A:$D,COLUMN(D:$D),FALSE),Ref_Chrono!$A:$A,0)),"")) | I11: =IF(C11="","",IFERROR(INDEX(Ref_Litho!$C:$C,MATCH(VLOOKUP(C11,Ref_GMU_Attributes!$A:$E,COLUMN(E:$E),FALSE),Ref_Litho!$A:$A,0)),"")) | J11: =IF(C11="","",IFERROR(INDEX(Ref_Litho!$C:$C,MATCH(VLOOKUP(C11,Ref_GMU_Attributes!$A:$F,COLUMN(F:$F),FALSE),Ref_Litho!$A:$A,0)),"")) | K11: =IF(C11="","",IFERROR(INDEX(Ref_Litho!$C:$C,MATCH(VLOOKUP(C11,Ref_GMU_Attributes!$A:$G,COLUMN(G:$G),FALSE),Ref_Litho!$A:$A,0)),""))
C12: =IF(B12="","",VALUE(LEFT(B12,FIND(":",B12)-1))) | E12: =IF(D12="","",VALUE(LEFT(D12,FIND(":",D12)-1))) | F12: =IF(C12="","",IFERROR(INDEX(Ref_LithoStratFormation!$C:$C,MATCH(VLOOKUP(C12,Ref_GMU_Attributes!$A:$B,COLUMN(B:$B),FALSE),Ref_LithoStratFormation!$A:$A,0)),"")) | G12: =IF(C12="","",IFERROR(INDEX(Ref_Chrono!$C:$C,MATCH(VLOOKUP(C12,Ref_GMU_Attributes!$A:$C,COLUMN(C:$C),FALSE),Ref_Chrono!$A:$A,0)),"")) | H12: =IF(C12="","",IFERROR(INDEX(Ref_Chrono!$C:$C,MATCH(VLOOKUP(C12,Ref_GMU_Attributes!$A:$D,COLUMN(D:$D),FALSE),Ref_Chrono!$A:$A,0)),"")) | I12: =IF(C12="","",IFERROR(INDEX(Ref_Litho!$C:$C,MATCH(VLOOKUP(C12,Ref_GMU_Attributes!$A:$E,COLUMN(E:$E),FALSE),Ref_Litho!$A:$A,0)),"")) | J12: =IF(C12="","",IFERROR(INDEX(Ref_Litho!$C:$C,MATCH(VLOOKUP(C12,Ref_GMU_Attributes!$A:$F,COLUMN(F:$F),FALSE),Ref_Litho!$A:$A,0)),"")) | K12: =IF(C12="","",IFERROR(INDEX(Ref_Litho!$C:$C,MATCH(VLOOKUP(C12,Ref_GMU_Attributes!$A:$G,COLUMN(G:$G),FALSE),Ref_Litho!$A:$A,0)),""))
C13: =IF(B13="","",VALUE(LEFT(B13,FIND(":",B13)-1))) | E13: =IF(D13="","",VALUE(LEFT(D13,FIND(":",D13)-1))) | F13: =IF(C13="","",IFERROR(INDEX(Ref_LithoStratFormation!$C:$C,MATCH(VLOOKUP(C13,Ref_GMU_Attributes!$A:$B,COLUMN(B:$B),FALSE),Ref_LithoStratFormation!$A:$A,0)),"")) | G13: =IF(C13="","",IFERROR(INDEX(Ref_Chrono!$C:$C,MATCH(VLOOKUP(C13,Ref_GMU_Attributes!$A:$C,COLUMN(C:$C),FALSE),Ref_Chrono!$A:$A,0)),"")) | H13: =IF(C13="","",IFERROR(INDEX(Ref_Chrono!$C:$C,MATCH(VLOOKUP(C13,Ref_GMU_Attributes!$A:$D,COLUMN(D:$D),FALSE),Ref_Chrono!$A:$A,0)),"")) | I13: =IF(C13="","",IFERROR(INDEX(Ref_Litho!$C:$C,MATCH(VLOOKUP(C13,Ref_GMU_Attributes!$A:$E,COLUMN(E:$E),FALSE),Ref_Litho!$A:$A,0)),"")) | J13: =IF(C13="","",IFERROR(INDEX(Ref_Litho!$C:$C,MATCH(VLOOKUP(C13,Ref_GMU_Attributes!$A:$F,COLUMN(F:$F),FALSE),Ref_Litho!$A:$A,0)),"")) | K13: =IF(C13="","",IFERROR(INDEX(Ref_Litho!$C:$C,MATCH(VLOOKUP(C13,Ref_GMU_Attributes!$A:$G,COLUMN(G:$G),FALSE),Ref_Litho!$A:$A,0)),""))
C14: =IF(B14="","",VALUE(LEFT(B14,FIND(":",B14)-1))) | E14: =IF(D14="","",VALUE(LEFT(D14,FIND(":",D14)-1))) | F14: =IF(C14="","",IFERROR(INDEX(Ref_LithoStratFormation!$C:$C,MATCH(VLOOKUP(C14,Ref_GMU_Attributes!$A:$B,COLUMN(B:$B),FALSE),Ref_LithoStratFormation!$A:$A,0)),"")) | G14: =IF(C14="","",IFERROR(INDEX(Ref_Chrono!$C:$C,MATCH(VLOOKUP(C14,Ref_GMU_Attributes!$A:$C,COLUMN(C:$C),FALSE),Ref_Chrono!$A:$A,0)),"")) | H14: =IF(C14="","",IFERROR(INDEX(Ref_Chrono!$C:$C,MATCH(VLOOKUP(C14,Ref_GMU_Attributes!$A:$D,COLUMN(D:$D),FALSE),Ref_Chrono!$A:$A,0)),"")) | I14: =IF(C14="","",IFERROR(INDEX(Ref_Litho!$C:$C,MATCH(VLOOKUP(C14,Ref_GMU_Attributes!$A:$E,COLUMN(E:$E),FALSE),Ref_Litho!$A:$A,0)),"")) | J14: =IF(C14="","",IFERROR(INDEX(Ref_Litho!$C:$C,MATCH(VLOOKUP(C14,Ref_GMU_Attributes!$A:$F,COLUMN(F:$F),FALSE),Ref_Litho!$A:$A,0)),"")) | K14: =IF(C14="","",IFERROR(INDEX(Ref_Litho!$C:$C,MATCH(VLOOKUP(C14,Ref_GMU_Attributes!$A:$G,COLUMN(G:$G),FALSE),Ref_Litho!$A:$A,0)),""))
C15: =IF(B15="","",VALUE(LEFT(B15,FIND(":",B15)-1))) | E15: =IF(D15="","",VALUE(LEFT(D15,FIND(":",D15)-1))) | F15: =IF(C15="","",IFERROR(INDEX(Ref_LithoStratFormation!$C:$C,MATCH(VLOOKUP(C15,Ref_GMU_Attributes!$A:$B,COLUMN(B:$B),FALSE),Ref_LithoStratFormation!$A:$A,0)),"")) | G15: =IF(C15="","",IFERROR(INDEX(Ref_Chrono!$C:$C,MATCH(VLOOKUP(C15,Ref_GMU_Attributes!$A:$C,COLUMN(C:$C),FALSE),Ref_Chrono!$A:$A,0)),"")) | H15: =IF(C15="","",IFERROR(INDEX(Ref_Chrono!$C:$C,MATCH(VLOOKUP(C15,Ref_GMU_Attributes!$A:$D,COLUMN(D:$D),FALSE),Ref_Chrono!$A:$A,0)),"")) | I15: =IF(C15="","",IFERROR(INDEX(Ref_Litho!$C:$C,MATCH(VLOOKUP(C15,Ref_GMU_Attributes!$A:$E,COLUMN(E:$E),FALSE),Ref_Litho!$A:$A,0)),"")) | J15: =IF(C15="","",IFERROR(INDEX(Ref_Litho!$C:$C,MATCH(VLOOKUP(C15,Ref_GMU_Attributes!$A:$F,COLUMN(F:$F),FALSE),Ref_Litho!$A:$A,0)),"")) | K15: =IF(C15="","",IFERROR(INDEX(Ref_Litho!$C:$C,MATCH(VLOOKUP(C15,Ref_GMU_Attributes!$A:$G,COLUMN(G:$G),FALSE),Ref_Litho!$A:$A,0)),""))
... C1000: =IF(B1000="","",VALUE(LEFT(B1000,FIND(":",B1000)-1))) | E1000: =IF(D1000="","",VALUE(LEFT(D1000,FIND(":",D1000)-1))) | F1000: =IF(C1000="","",IFERROR(INDEX(Ref_LithoStratFormation!$C:$C,MATCH(VLOOKUP(C1000,Ref_GMU_Attributes!$A:$B,COLUMN(B:$B),FALSE),Ref_LithoStratFormation!$A:$A,0)),"")) | G1000: =IF(C1000="","",IFERROR(INDEX(Ref_Chrono!$C:$C,MATCH(VLOOKUP(C1000,Ref_GMU_Attributes!$A:$C,COLUMN(C:$C),FALSE),Ref_Chrono!$A:$A,0)),"")) | H1000: =IF(C1000="","",IFERROR(INDEX(Ref_Chrono!$C:$C,MATCH(VLOOKUP(C1000,Ref_GMU_Attributes!$A:$D,COLUMN(D:$D),FALSE),Ref_Chrono!$A:$A,0)),"")) | I1000: =IF(C1000="","",IFERROR(INDEX(Ref_Litho!$C:$C,MATCH(VLOOKUP(C1000,Ref_GMU_Attributes!$A:$E,COLUMN(E:$E),FALSE),Ref_Litho!$A:$A,0)),"")) | J1000: =IF(C1000="","",IFERROR(INDEX(Ref_Litho!$C:$C,MATCH(VLOOKUP(C1000,Ref_GMU_Attributes!$A:$F,COLUMN(F:$F),FALSE),Ref_Litho!$A:$A,0)),"")) | K1000: =IF(C1000="","",IFERROR(INDEX(Ref_Litho!$C:$C,MATCH(VLOOKUP(C1000,Ref_GMU_Attributes!$A:$G,COLUMN(G:$G),FALSE),Ref_Litho!$A:$A,0)),""))

Sheet Unconsolidated_Deposits_PLG
A1: User_Code | B1: LITSTRAT_Display | C1: LITSTRAT | D1: LITHO_Display | E1: LITHO | F1: CHRONO_TOP_Display | G1: CHRONO_TOP | H1: CHRONO_BASE_Display | I1: CHRONO_BASE
A2: UNCO_001 | C2: =IF(B2="","",VALUE(LEFT(B2,FIND(":",B2)-1))) | E2: =IF(D2="","",VALUE(LEFT(D2,FIND(":",D2)-1))) | G2: =IF(F2="","",VALUE(LEFT(F2,FIND(":",F2)-1))) | I2: =IF(H2="","",VALUE(LEFT(H2,FIND(":",H2)-1)))
A3: UNCO_002 | C3: =IF(B3="","",VALUE(LEFT(B3,FIND(":",B3)-1))) | E3: =IF(D3="","",VALUE(LEFT(D3,FIND(":",D3)-1))) | G3: =IF(F3="","",VALUE(LEFT(F3,FIND(":",F3)-1))) | I3: =IF(H3="","",VALUE(LEFT(H3,FIND(":",H3)-1)))
C4: =IF(B4="","",VALUE(LEFT(B4,FIND(":",B4)-1))) | E4: =IF(D4="","",VALUE(LEFT(D4,FIND(":",D4)-1))) | G4: =IF(F4="","",VALUE(LEFT(F4,FIND(":",F4)-1))) | I4: =IF(H4="","",VALUE(LEFT(H4,FIND(":",H4)-1)))
C5: =IF(B5="","",VALUE(LEFT(B5,FIND(":",B5)-1))) | E5: =IF(D5="","",VALUE(LEFT(D5,FIND(":",D5)-1))) | G5: =IF(F5="","",VALUE(LEFT(F5,FIND(":",F5)-1))) | I5: =IF(H5="","",VALUE(LEFT(H5,FIND(":",H5)-1)))
C6: =IF(B6="","",VALUE(LEFT(B6,FIND(":",B6)-1))) | E6: =IF(D6="","",VALUE(LEFT(D6,FIND(":",D6)-1))) | G6: =IF(F6="","",VALUE(LEFT(F6,FIND(":",F6)-1))) | I6: =IF(H6="","",VALUE(LEFT(H6,FIND(":",H6)-1)))
C7: =IF(B7="","",VALUE(LEFT(B7,FIND(":",B7)-1))) | E7: =IF(D7="","",VALUE(LEFT(D7,FIND(":",D7)-1))) | G7: =IF(F7="","",VALUE(LEFT(F7,FIND(":",F7)-1))) | I7: =IF(H7="","",VALUE(LEFT(H7,FIND(":",H7)-1)))
C8: =IF(B8="","",VALUE(LEFT(B8,FIND(":",B8)-1))) | E8: =IF(D8="","",VALUE(LEFT(D8,FIND(":",D8)-1))) | G8: =IF(F8="","",VALUE(LEFT(F8,FIND(":",F8)-1))) | I8: =IF(H8="","",VALUE(LEFT(H8,FIND(":",H8)-1)))
C9: =IF(B9="","",VALUE(LEFT(B9,FIND(":",B9)-1))) | E9: =IF(D9="","",VALUE(LEFT(D9,FIND(":",D9)-1))) | G9: =IF(F9="","",VALUE(LEFT(F9,FIND(":",F9)-1))) | I9: =IF(H9="","",VALUE(LEFT(H9,FIND(":",H9)-1)))
C10: =IF(B10="","",VALUE(LEFT(B10,FIND(":",B10)-1))) | E10: =IF(D10="","",VALUE(LEFT(D10,FIND(":",D10)-1))) | G10: =IF(F10="","",VALUE(LEFT(F10,FIND(":",F10)-1))) | I10: =IF(H10="","",VALUE(LEFT(H10,FIND(":",H10)-1)))
C11: =IF(B11="","",VALUE(LEFT(B11,FIND(":",B11)-1))) | E11: =IF(D11="","",VALUE(LEFT(D11,FIND(":",D11)-1))) | G11: =IF(F11="","",VALUE(LEFT(F11,FIND(":",F11)-1))) | I11: =IF(H11="","",VALUE(LEFT(H11,FIND(":",H11)-1)))
C12: =IF(B12="","",VALUE(LEFT(B12,FIND(":",B12)-1))) | E12: =IF(D12="","",VALUE(LEFT(D12,FIND(":",D12)-1))) | G12: =IF(F12="","",VALUE(LEFT(F12,FIND(":",F12)-1))) | I12: =IF(H12="","",VALUE(LEFT(H12,FIND(":",H12)-1)))
C13: =IF(B13="","",VALUE(LEFT(B13,FIND(":",B13)-1))) | E13: =IF(D13="","",VALUE(LEFT(D13,FIND(":",D13)-1))) | G13: =IF(F13="","",VALUE(LEFT(F13,FIND(":",F13)-1))) | I13: =IF(H13="","",VALUE(LEFT(H13,FIND(":",H13)-1)))
C14: =IF(B14="","",VALUE(LEFT(B14,FIND(":",B14)-1))) | E14: =IF(D14="","",VALUE(LEFT(D14,FIND(":",D14)-1))) | G14: =IF(F14="","",VALUE(LEFT(F14,FIND(":",F14)-1))) | I14: =IF(H14="","",VALUE(LEFT(H14,FIND(":",H14)-1)))
C15: =IF(B15="","",VALUE(LEFT(B15,FIND(":",B15)-1))) | E15: =IF(D15="","",VALUE(LEFT(D15,FIND(":",D15)-1))) | G15: =IF(F15="","",VALUE(LEFT(F15,FIND(":",F15)-1))) | I15: =IF(H15="","",VALUE(LEFT(H15,FIND(":",H15)-1)))
... C1000: =IF(B1000="","",VALUE(LEFT(B1000,FIND(":",B1000)-1))) | E1000: =IF(D1000="","",VALUE(LEFT(D1000,FIND(":",D1000)-1))) | G1000: =IF(F1000="","",VALUE(LEFT(F1000,FIND(":",F1000)-1))) | I1000: =IF(H1000="","",VALUE(LEFT(H1000,FIND(":",H1000)-1)))

Sheet Fossils_PT
A1: User_Code | B1: DIVISION_Display | C1: DIVISION | D1: SYSTEM_1_Display | E1: SYSTEM_1 | F1: SYSTEM_2_Display | G1: SYSTEM_2 | H1: SYSTEM_3_Display | I1: SYSTEM_3
A2: FOSSIL_001 | C2: =IF(B2="","",VALUE(LEFT(B2,FIND(":",B2)-1))) | E2: =IF(D2="","",VALUE(LEFT(D2,FIND(":",D2)-1))) | G2: =IF(F2="","",VALUE(LEFT(F2,FIND(":",F2)-1))) | I2: =IF(H2="","",VALUE(LEFT(H2,FIND(":",H2)-1)))
A3: FOSSIL_002 | C3: =IF(B3="","",VALUE(LEFT(B3,FIND(":",B3)-1))) | E3: =IF(D3="","",VALUE(LEFT(D3,FIND(":",D3)-1))) | G3: =IF(F3="","",VALUE(LEFT(F3,FIND(":",F3)-1))) | I3: =IF(H3="","",VALUE(LEFT(H3,FIND(":",H3)-1)))
C4: =IF(B4="","",VALUE(LEFT(B4,FIND(":",B4)-1))) | E4: =IF(D4="","",VALUE(LEFT(D4,FIND(":",D4)-1))) | G4: =IF(F4="","",VALUE(LEFT(F4,FIND(":",F4)-1))) | I4: =IF(H4="","",VALUE(LEFT(H4,FIND(":",H4)-1)))
C5: =IF(B5="","",VALUE(LEFT(B5,FIND(":",B5)-1))) | E5: =IF(D5="","",VALUE(LEFT(D5,FIND(":",D5)-1))) | G5: =IF(F5="","",VALUE(LEFT(F5,FIND(":",F5)-1))) | I5: =IF(H5="","",VALUE(LEFT(H5,FIND(":",H5)-1)))
C6: =IF(B6="","",VALUE(LEFT(B6,FIND(":",B6)-1))) | E6: =IF(D6="","",VALUE(LEFT(D6,FIND(":",D6)-1))) | G6: =IF(F6="","",VALUE(LEFT(F6,FIND(":",F6)-1))) | I6: =IF(H6="","",VALUE(LEFT(H6,FIND(":",H6)-1)))
C7: =IF(B7="","",VALUE(LEFT(B7,FIND(":",B7)-1))) | E7: =IF(D7="","",VALUE(LEFT(D7,FIND(":",D7)-1))) | G7: =IF(F7="","",VALUE(LEFT(F7,FIND(":",F7)-1))) | I7: =IF(H7="","",VALUE(LEFT(H7,FIND(":",H7)-1)))
C8: =IF(B8="","",VALUE(LEFT(B8,FIND(":",B8)-1))) | E8: =IF(D8="","",VALUE(LEFT(D8,FIND(":",D8)-1))) | G8: =IF(F8="","",VALUE(LEFT(F8,FIND(":",F8)-1))) | I8: =IF(H8="","",VALUE(LEFT(H8,FIND(":",H8)-1)))
C9: =IF(B9="","",VALUE(LEFT(B9,FIND(":",B9)-1))) | E9: =IF(D9="","",VALUE(LEFT(D9,FIND(":",D9)-1))) | G9: =IF(F9="","",VALUE(LEFT(F9,FIND(":",F9)-1))) | I9: =IF(H9="","",VALUE(LEFT(H9,FIND(":",H9)-1)))
C10: =IF(B10="","",VALUE(LEFT(B10,FIND(":",B10)-1))) | E10: =IF(D10="","",VALUE(LEFT(D10,FIND(":",D10)-1))) | G10: =IF(F10="","",VALUE(LEFT(F10,FIND(":",F10)-1))) | I10: =IF(H10="","",VALUE(LEFT(H10,FIND(":",H10)-1)))
C11: =IF(B11="","",VALUE(LEFT(B11,FIND(":",B11)-1))) | E11: =IF(D11="","",VALUE(LEFT(D11,FIND(":",D11)-1))) | G11: =IF(F11="","",VALUE(LEFT(F11,FIND(":",F11)-1))) | I11: =IF(H11="","",VALUE(LEFT(H11,FIND(":",H11)-1)))
C12: =IF(B12="","",VALUE(LEFT(B12,FIND(":",B12)-1))) | E12: =IF(D12="","",VALUE(LEFT(D12,FIND(":",D12)-1))) | G12: =IF(F12="","",VALUE(LEFT(F12,FIND(":",F12)-1))) | I12: =IF(H12="","",VALUE(LEFT(H12,FIND(":",H12)-1)))
C13: =IF(B13="","",VALUE(LEFT(B13,FIND(":",B13)-1))) | E13: =IF(D13="","",VALUE(LEFT(D13,FIND(":",D13)-1))) | G13: =IF(F13="","",VALUE(LEFT(F13,FIND(":",F13)-1))) | I13: =IF(H13="","",VALUE(LEFT(H13,FIND(":",H13)-1)))
C14: =IF(B14="","",VALUE(LEFT(B14,FIND(":",B14)-1))) | E14: =IF(D14="","",VALUE(LEFT(D14,FIND(":",D14)-1))) | G14: =IF(F14="","",VALUE(LEFT(F14,FIND(":",F14)-1))) | I14: =IF(H14="","",VALUE(LEFT(H14,FIND(":",H14)-1)))
C15: =IF(B15="","",VALUE(LEFT(B15,FIND(":",B15)-1))) | E15: =IF(D15="","",VALUE(LEFT(D15,FIND(":",D15)-1))) | G15: =IF(F15="","",VALUE(LEFT(F15,FIND(":",F15)-1))) | I15: =IF(H15="","",VALUE(LEFT(H15,FIND(":",H15)-1)))
... C1000: =IF(B1000="","",VALUE(LEFT(B1000,FIND(":",B1000)-1))) | E1000: =IF(D1000="","",VALUE(LEFT(D1000,FIND(":",D1000)-1))) | G1000: =IF(F1000="","",VALUE(LEFT(F1000,FIND(":",F1000)-1))) | I1000: =IF(H1000="","",VALUE(LEFT(H1000,FIND(":",H1000)-1)))

Sheet Tectonic_Boundaries_L
A1: User_Code | B1: KIND_Display | C1: KIND | D1: LIM_TYP_Display | E1: LIM_TYP | F1: HIERA_Display | G1: HIERA | H1: STATUS_Display | I1: STATUS | J1: NAME
A2: TECTO_001 | C2: =IF(B2="","",VALUE(LEFT(B2,FIND(":",B2)-1))) | E2: =IF(D2="","",VALUE(LEFT(D2,FIND(":",D2)-1))) | G2: =IF(F2="","",VALUE(LEFT(F2,FIND(":",F2)-1))) | I2: =IF(H2="","",VALUE(LEFT(H2,FIND(":",H2)-1)))
A3: TECTO_002 | C3: =IF(B3="","",VALUE(LEFT(B3,FIND(":",B3)-1))) | E3: =IF(D3="","",VALUE(LEFT(D3,FIND(":",D3)-1))) | G3: =IF(F3="","",VALUE(LEFT(F3,FIND(":",F3)-1))) | I3: =IF(H3="","",VALUE(LEFT(H3,FIND(":",H3)-1)))
C4: =IF(B4="","",VALUE(LEFT(B4,FIND(":",B4)-1))) | E4: =IF(D4="","",VALUE(LEFT(D4,FIND(":",D4)-1))) | G4: =IF(F4="","",VALUE(LEFT(F4,FIND(":",F4)-1))) | I4: =IF(H4="","",VALUE(LEFT(H4,FIND(":",H4)-1)))
C5: =IF(B5="","",VALUE(LEFT(B5,FIND(":",B5)-1))) | E5: =IF(D5="","",VALUE(LEFT(D5,FIND(":",D5)-1))) | G5: =IF(F5="","",VALUE(LEFT(F5,FIND(":",F5)-1))) | I5: =IF(H5="","",VALUE(LEFT(H5,FIND(":",H5)-1)))
C6: =IF(B6="","",VALUE(LEFT(B6,FIND(":",B6)-1))) | E6: =IF(D6="","",VALUE(LEFT(D6,FIND(":",D6)-1))) | G6: =IF(F6="","",VALUE(LEFT(F6,FIND(":",F6)-1))) | I6: =IF(H6="","",VALUE(LEFT(H6,FIND(":",H6)-1)))
C7: =IF(B7="","",VALUE(LEFT(B7,FIND(":",B7)-1))) | E7: =IF(D7="","",VALUE(LEFT(D7,FIND(":",D7)-1))) | G7: =IF(F7="","",VALUE(LEFT(F7,FIND(":",F7)-1))) | I7: =IF(H7="","",VALUE(LEFT(H7,FIND(":",H7)-1)))
C8: =IF(B8="","",VALUE(LEFT(B8,FIND(":",B8)-1))) | E8: =IF(D8="","",VALUE(LEFT(D8,FIND(":",D8)-1))) | G8: =IF(F8="","",VALUE(LEFT(F8,FIND(":",F8)-1))) | I8: =IF(H8="","",VALUE(LEFT(H8,FIND(":",H8)-1)))
C9: =IF(B9="","",VALUE(LEFT(B9,FIND(":",B9)-1))) | E9: =IF(D9="","",VALUE(LEFT(D9,FIND(":",D9)-1))) | G9: =IF(F9="","",VALUE(LEFT(F9,FIND(":",F9)-1))) | I9: =IF(H9="","",VALUE(LEFT(H9,FIND(":",H9)-1)))
C10: =IF(B10="","",VALUE(LEFT(B10,FIND(":",B10)-1))) | E10: =IF(D10="","",VALUE(LEFT(D10,FIND(":",D10)-1))) | G10: =IF(F10="","",VALUE(LEFT(F10,FIND(":",F10)-1))) | I10: =IF(H10="","",VALUE(LEFT(H10,FIND(":",H10)-1)))
C11: =IF(B11="","",VALUE(LEFT(B11,FIND(":",B11)-1))) | E11: =IF(D11="","",VALUE(LEFT(D11,FIND(":",D11)-1))) | G11: =IF(F11="","",VALUE(LEFT(F11,FIND(":",F11)-1))) | I11: =IF(H11="","",VALUE(LEFT(H11,FIND(":",H11)-1)))
C12: =IF(B12="","",VALUE(LEFT(B12,FIND(":",B12)-1))) | E12: =IF(D12="","",VALUE(LEFT(D12,FIND(":",D12)-1))) | G12: =IF(F12="","",VALUE(LEFT(F12,FIND(":",F12)-1))) | I12: =IF(H12="","",VALUE(LEFT(H12,FIND(":",H12)-1)))
C13: =IF(B13="","",VALUE(LEFT(B13,FIND(":",B13)-1))) | E13: =IF(D13="","",VALUE(LEFT(D13,FIND(":",D13)-1))) | G13: =IF(F13="","",VALUE(LEFT(F13,FIND(":",F13)-1))) | I13: =IF(H13="","",VALUE(LEFT(H13,FIND(":",H13)-1)))
C14: =IF(B14="","",VALUE(LEFT(B14,FIND(":",B14)-1))) | E14: =IF(D14="","",VALUE(LEFT(D14,FIND(":",D14)-1))) | G14: =IF(F14="","",VALUE(LEFT(F14,FIND(":",F14)-1))) | I14: =IF(H14="","",VALUE(LEFT(H14,FIND(":",H14)-1)))
C15: =IF(B15="","",VALUE(LEFT(B15,FIND(":",B15)-1))) | E15: =IF(D15="","",VALUE(LEFT(D15,FIND(":",D15)-1))) | G15: =IF(F15="","",VALUE(LEFT(F15,FIND(":",F15)-1))) | I15: =IF(H15="","",VALUE(LEFT(H15,FIND(":",H15)-1)))
... C1000: =IF(B1000="","",VALUE(LEFT(B1000,FIND(":",B1000)-1))) | E1000: =IF(D1000="","",VALUE(LEFT(D1000,FIND(":",D1000)-1))) | G1000: =IF(F1000="","",VALUE(LEFT(F1000,FIND(":",F1000)-1))) | I1000: =IF(H1000="","",VALUE(LEFT(H1000,FIND(":",H1000)-1)))

Sheet Instability_Structures_L
A1: User_Code | B1: KIND_Display | C1: KIND | D1: Notes
A2: INSTABILITY_STRUCTURES_L_001 | C2: =IF(B2="","",VALUE(LEFT(B2,FIND(":",B2)-1)))
C3: =IF(B3="","",VALUE(LEFT(B3,FIND(":",B3)-1)))
C4: =IF(B4="","",VALUE(LEFT(B4,FIND(":",B4)-1)))
C5: =IF(B5="","",VALUE(LEFT(B5,FIND(":",B5)-1)))
C6: =IF(B6="","",VALUE(LEFT(B6,FIND(":",B6)-1)))
C7: =IF(B7="","",VALUE(LEFT(B7,FIND(":",B7)-1)))
C8: =IF(B8="","",VALUE(LEFT(B8,FIND(":",B8)-1)))
C9: =IF(B9="","",VALUE(LEFT(B9,FIND(":",B9)-1)))
C10: =IF(B10="","",VALUE(LEFT(B10,FIND(":",B10)-1)))
C11: =IF(B11="","",VALUE(LEFT(B11,FIND(":",B11)-1)))
C12: =IF(B12="","",VALUE(LEFT(B12,FIND(":",B12)-1)))
C13: =IF(B13="","",VALUE(LEFT(B13,FIND(":",B13)-1)))
C14: =IF(B14="","",VALUE(LEFT(B14,FIND(":",B14)-1)))
... C1000: =IF(B1000="","",VALUE(LEFT(B1000,FIND(":",B1000)-1)))

Sheet Glacial_Periglacial_Structures_L
A1: User_Code | B1: KIND_Display | C1: KIND | D1: Notes
A2: GLACIAL_PERIGLACIAL_STRUCTURES_L_001 | C2: =IF(B2="","",VALUE(LEFT(B2,FIND(":",B2)-1)))
C3: =IF(B3="","",VALUE(LEFT(B3,FIND(":",B3)-1)))
C4: =IF(B4="","",VALUE(LEFT(B4,FIND(":",B4)-1)))
C5: =IF(B5="","",VALUE(LEFT(B5,FIND(":",B5)-1)))
C6: =IF(B6="","",VALUE(LEFT(B6,FIND(":",B6)-1)))
C7: =IF(B7="","",VALUE(LEFT(B7,FIND(":",B7)-1)))
C8: =IF(B8="","",VALUE(LEFT(B8,FIND(":",B8)-1)))
C9: =IF(B9="","",VALUE(LEFT(B9,FIND(":",B9)-1)))
C10: =IF(B10="","",VALUE(LEFT(B10,FIND(":",B10)-1)))
C11: =IF(B11="","",VALUE(LEFT(B11,FIND(":",B11)-1)))
C12: =IF(B12="","",VALUE(LEFT(B12,FIND(":",B12)-1)))
C13: =IF(B13="","",VALUE(LEFT(B13,FIND(":",B13)-1)))
C14: =IF(B14="","",VALUE(LEFT(B14,FIND(":",B14)-1)))
... C1000: =IF(B1000="","",VALUE(LEFT(B1000,FIND(":",B1000)-1)))

Sheet Erosional_Structures_L
A1: User_Code | B1: KIND_Display | C1: KIND | D1: Notes
A2: EROSIONAL_STRUCTURES_L_001 | C2: =IF(B2="","",VALUE(LEFT(B2,FIND(":",B2)-1)))
C3: =IF(B3="","",VALUE(LEFT(B3,FIND(":",B3)-1)))
C4: =IF(B4="","",VALUE(LEFT(B4,FIND(":",B4)-1)))
C5: =IF(B5="","",VALUE(LEFT(B5,FIND(":",B5)-1)))
C6: =IF(B6="","",VALUE(LEFT(B6,FIND(":",B6)-1)))
C7: =IF(B7="","",VALUE(LEFT(B7,FIND(":",B7)-1)))
C8: =IF(B8="","",VALUE(LEFT(B8,FIND(":",B8)-1)))
C9: =IF(B9="","",VALUE(LEFT(B9,FIND(":",B9)-1)))
C10: =IF(B10="","",VALUE(LEFT(B10,FIND(":",B10)-1)))
C11: =IF(B11="","",VALUE(LEFT(B11,FIND(":",B11)-1)))
C12: =IF(B12="","",VALUE(LEFT(B12,FIND(":",B12)-1)))
C13: =IF(B13="","",VALUE(LEFT(B13,FIND(":",B13)-1)))
C14: =IF(B14="","",VALUE(LEFT(B14,FIND(":",B14)-1)))
... C1000: =IF(B1000="","",VALUE(LEFT(B1000,FIND(":",B1000)-1)))

Sheet Alluvial_Lacustrine_Structures_L
A1: User_Code | B1: KIND_Display | C1: KIND | D1: Notes
A2: ALLUVIAL_LACUSTRINE_STRUCTURES_L_001 | C2: =IF(B2="","",VALUE(LEFT(B2,FIND(":",B2)-1)))
C3: =IF(B3="","",VALUE(LEFT(B3,FIND(":",B3)-1)))
C4: =IF(B4="","",VALUE(LEFT(B4,FIND(":",B4)-1)))
C5: =IF(B5="","",VALUE(LEFT(B5,FIND(":",B5)-1)))
C6: =IF(B6="","",VALUE(LEFT(B6,FIND(":",B6)-1)))
C7: =IF(B7="","",VALUE(LEFT(B7,FIND(":",B7)-1)))
C8: =IF(B8="","",VALUE(LEFT(B8,FIND(":",B8)-1)))
C9: =IF(B9="","",VALUE(LEFT(B9,FIND(":",B9)-1)))
C10: =IF(B10="","",VALUE(LEFT(B10,FIND(":",B10)-1)))
C11: =IF(B11="","",VALUE(LEFT(B11,FIND(":",B11)-1)))
C12: =IF(B12="","",VALUE(LEFT(B12,FIND(":",B12)-1)))
C13: =IF(B13="","",VALUE(LEFT(B13,FIND(":",B13)-1)))
C14: =IF(B14="","",VALUE(LEFT(B14,FIND(":",B14)-1)))
... C1000: =IF(B1000="","",VALUE(LEFT(B1000,FIND(":",B1000)-1)))

Sheet Deformation_Structures_L
A1: User_Code | B1: KIND_Display | C1: KIND | D1: Notes
A2: DEFORMATION_STRUCTURES_L_001 | C2: =IF(B2="","",VALUE(LEFT(B2,FIND(":",B2)-1)))
C3: =IF(B3="","",VALUE(LEFT(B3,FIND(":",B3)-1)))
C4: =IF(B4="","",VALUE(LEFT(B4,FIND(":",B4)-1)))
C5: =IF(B5="","",VALUE(LEFT(B5,FIND(":",B5)-1)))
C6: =IF(B6="","",VALUE(LEFT(B6,FIND(":",B6)-1)))
C7: =IF(B7="","",VALUE(LEFT(B7,FIND(":",B7)-1)))
C8: =IF(B8="","",VALUE(LEFT(B8,FIND(":",B8)-1)))
C9: =IF(B9="","",VALUE(LEFT(B9,FIND(":",B9)-1)))
C10: =IF(B10="","",VALUE(LEFT(B10,FIND(":",B10)-1)))
C11: =IF(B11="","",VALUE(LEFT(B11,FIND(":",B11)-1)))
C12: =IF(B12="","",VALUE(LEFT(B12,FIND(":",B12)-1)))
C13: =IF(B13="","",VALUE(LEFT(B13,FIND(":",B13)-1)))
C14: =IF(B14="","",VALUE(LEFT(B14,FIND(":",B14)-1)))
... C1000: =IF(B1000="","",VALUE(LEFT(B1000,FIND(":",B1000)-1)))

Sheet Mineralised_Zone_L
A1: User_Code | B1: KIND_Display | C1: KIND | D1: Notes
A2: MINERALISED_ZONE_L_001 | C2: =IF(B2="","",VALUE(LEFT(B2,FIND(":",B2)-1)))
C3: =IF(B3="","",VALUE(LEFT(B3,FIND(":",B3)-1)))
C4: =IF(B4="","",VALUE(LEFT(B4,FIND(":",B4)-1)))
C5: =IF(B5="","",VALUE(LEFT(B5,FIND(":",B5)-1)))
C6: =IF(B6="","",VALUE(LEFT(B6,FIND(":",B6)-1)))
C7: =IF(B7="","",VALUE(LEFT(B7,FIND(":",B7)-1)))
C8: =IF(B8="","",VALUE(LEFT(B8,FIND(":",B8)-1)))
C9: =IF(B9="","",VALUE(LEFT(B9,FIND(":",B9)-1)))
C10: =IF(B10="","",VALUE(LEFT(B10,FIND(":",B10)-1)))
C11: =IF(B11="","",VALUE(LEFT(B11,FIND(":",B11)-1)))
C12: =IF(B12="","",VALUE(LEFT(B12,FIND(":",B12)-1)))
C13: =IF(B13="","",VALUE(LEFT(B13,FIND(":",B13)-1)))
C14: =IF(B14="","",VALUE(LEFT(B14,FIND(":",B14)-1)))
... C1000: =IF(B1000="","",VALUE(LEFT(B1000,FIND(":",B1000)-1)))

Sheet Prominent_Lithological_Features_L
A1: User_Code | B1: KIND_Display | C1: KIND | D1: LITHO_Display | E1: LITHO | F1: Notes
A2: PROMINENT_LITHOLOGICAL_FEATURES_L_001 | C2: =IF(B2="","",VALUE(LEFT(B2,FIND(":",B2)-1))) | E2: =IF(D2="","",VALUE(LEFT(D2,FIND(":",D2)-1)))
C3: =IF(B3="","",VALUE(LEFT(B3,FIND(":",B3)-1))) | E3: =IF(D3="","",VALUE(LEFT(D3,FIND(":",D3)-1)))
C4: =IF(B4="","",VALUE(LEFT(B4,FIND(":",B4)-1))) | E4: =IF(D4="","",VALUE(LEFT(D4,FIND(":",D4)-1)))
C5: =IF(B5="","",VALUE(LEFT(B5,FIND(":",B5)-1))) | E5: =IF(D5="","",VALUE(LEFT(D5,FIND(":",D5)-1)))
C6: =IF(B6="","",VALUE(LEFT(B6,FIND(":",B6)-1))) | E6: =IF(D6="","",VALUE(LEFT(D6,FIND(":",D6)-1)))
C7: =IF(B7="","",VALUE(LEFT(B7,FIND(":",B7)-1))) | E7: =IF(D7="","",VALUE(LEFT(D7,FIND(":",D7)-1)))
C8: =IF(B8="","",VALUE(LEFT(B8,FIND(":",B8)-1))) | E8: =IF(D8="","",VALUE(LEFT(D8,FIND(":",D8)-1)))
C9: =IF(B9="","",VALUE(LEFT(B9,FIND(":",B9)-1))) | E9: =IF(D9="","",VALUE(LEFT(D9,FIND(":",D9)-1)))
C10: =IF(B10="","",VALUE(LEFT(B10,FIND(":",B10)-1))) | E10: =IF(D10="","",VALUE(LEFT(D10,FIND(":",D10)-1)))
C11: =IF(B11="","",VALUE(LEFT(B11,FIND(":",B11)-1))) | E11: =IF(D11="","",VALUE(LEFT(D11,FIND(":",D11)-1)))
C12: =IF(B12="","",VALUE(LEFT(B12,FIND(":",B12)-1))) | E12: =IF(D12="","",VALUE(LEFT(D12,FIND(":",D12)-1)))
C13: =IF(B13="","",VALUE(LEFT(B13,FIND(":",B13)-1))) | E13: =IF(D13="","",VALUE(LEFT(D13,FIND(":",D13)-1)))
C14: =IF(B14="","",VALUE(LEFT(B14,FIND(":",B14)-1))) | E14: =IF(D14="","",VALUE(LEFT(D14,FIND(":",D14)-1)))
... C1000: =IF(B1000="","",VALUE(LEFT(B1000,FIND(":",B1000)-1))) | E1000: =IF(D1000="","",VALUE(LEFT(D1000,FIND(":",D1000)-1)))

Sheet Geological_Outlines_L
A1: User_Code | B1: KIND_Display | C1: KIND | D1: Notes
A2: GEOLOGICAL_OUTLINES_L_001 | C2: =IF(B2="","",VALUE(LEFT(B2,FIND(":",B2)-1)))
C3: =IF(B3="","",VALUE(LEFT(B3,FIND(":",B3)-1)))
C4: =IF(B4="","",VALUE(LEFT(B4,FIND(":",B4)-1)))
C5: =IF(B5="","",VALUE(LEFT(B5,FIND(":",B5)-1)))
C6: =IF(B6="","",VALUE(LEFT(B6,FIND(":",B6)-1)))
C7: =IF(B7="","",VALUE(LEFT(B7,FIND(":",B7)-1)))
C8: =IF(B8="","",VALUE(LEFT(B8,FIND(":",B8)-1)))
C9: =IF(B9="","",VALUE(LEFT(B9,FIND(":",B9)-1)))
C10: =IF(B10="","",VALUE(LEFT(B10,FIND(":",B10)-1)))
C11: =IF(B11="","",VALUE(LEFT(B11,FIND(":",B11)-1)))
C12: =IF(B12="","",VALUE(LEFT(B12,FIND(":",B12)-1)))
C13: =IF(B13="","",VALUE(LEFT(B13,FIND(":",B13)-1)))
C14: =IF(B14="","",VALUE(LEFT(B14,FIND(":",B14)-1)))
... C1000: =IF(B1000="","",VALUE(LEFT(B1000,FIND(":",B1000)-1)))

Sheet Contour_Lines_Bedrock_L
A1: User_Code | B1: KIND_Display | C1: KIND | D1: ALTITUDE | E1: LITSTRAT_Display | F1: LITSTRAT | G1: TYPE_Display | H1: TYPE | I1: Notes
A2: CONTOUR_LINES_BEDROCK_L_001 | C2: =IF(B2="","",VALUE(LEFT(B2,FIND(":",B2)-1))) | F2: =IF(E2="","",VALUE(LEFT(E2,FIND(":",E2)-1))) | H2: =IF(G2="","",VALUE(LEFT(G2,FIND(":",G2)-1)))
C3: =IF(B3="","",VALUE(LEFT(B3,FIND(":",B3)-1))) | F3: =IF(E3="","",VALUE(LEFT(E3,FIND(":",E3)-1))) | H3: =IF(G3="","",VALUE(LEFT(G3,FIND(":",G3)-1)))
C4: =IF(B4="","",VALUE(LEFT(B4,FIND(":",B4)-1))) | F4: =IF(E4="","",VALUE(LEFT(E4,FIND(":",E4)-1))) | H4: =IF(G4="","",VALUE(LEFT(G4,FIND(":",G4)-1)))
C5: =IF(B5="","",VALUE(LEFT(B5,FIND(":",B5)-1))) | F5: =IF(E5="","",VALUE(LEFT(E5,FIND(":",E5)-1))) | H5: =IF(G5="","",VALUE(LEFT(G5,FIND(":",G5)-1)))
C6: =IF(B6="","",VALUE(LEFT(B6,FIND(":",B6)-1))) | F6: =IF(E6="","",VALUE(LEFT(E6,FIND(":",E6)-1))) | H6: =IF(G6="","",VALUE(LEFT(G6,FIND(":",G6)-1)))
C7: =IF(B7="","",VALUE(LEFT(B7,FIND(":",B7)-1))) | F7: =IF(E7="","",VALUE(LEFT(E7,FIND(":",E7)-1))) | H7: =IF(G7="","",VALUE(LEFT(G7,FIND(":",G7)-1)))
C8: =IF(B8="","",VALUE(LEFT(B8,FIND(":",B8)-1))) | F8: =IF(E8="","",VALUE(LEFT(E8,FIND(":",E8)-1))) | H8: =IF(G8="","",VALUE(LEFT(G8,FIND(":",G8)-1)))
C9: =IF(B9="","",VALUE(LEFT(B9,FIND(":",B9)-1))) | F9: =IF(E9="","",VALUE(LEFT(E9,FIND(":",E9)-1))) | H9: =IF(G9="","",VALUE(LEFT(G9,FIND(":",G9)-1)))
C10: =IF(B10="","",VALUE(LEFT(B10,FIND(":",B10)-1))) | F10: =IF(E10="","",VALUE(LEFT(E10,FIND(":",E10)-1))) | H10: =IF(G10="","",VALUE(LEFT(G10,FIND(":",G10)-1)))
C11: =IF(B11="","",VALUE(LEFT(B11,FIND(":",B11)-1))) | F11: =IF(E11="","",VALUE(LEFT(E11,FIND(":",E11)-1))) | H11: =IF(G11="","",VALUE(LEFT(G11,FIND(":",G11)-1)))
C12: =IF(B12="","",VALUE(LEFT(B12,FIND(":",B12)-1))) | F12: =IF(E12="","",VALUE(LEFT(E12,FIND(":",E12)-1))) | H12: =IF(G12="","",VALUE(LEFT(G12,FIND(":",G12)-1)))
C13: =IF(B13="","",VALUE(LEFT(B13,FIND(":",B13)-1))) | F13: =IF(E13="","",VALUE(LEFT(E13,FIND(":",E13)-1))) | H13: =IF(G13="","",VALUE(LEFT(G13,FIND(":",G13)-1)))
C14: =IF(B14="","",VALUE(LEFT(B14,FIND(":",B14)-1))) | F14: =IF(E14="","",VALUE(LEFT(E14,FIND(":",E14)-1))) | H14: =IF(G14="","",VALUE(LEFT(G14,FIND(":",G14)-1)))
... C1000: =IF(B1000="","",VALUE(LEFT(B1000,FIND(":",B1000)-1))) | F1000: =IF(E1000="","",VALUE(LEFT(E1000,FIND(":",E1000)-1))) | H1000: =IF(G1000="","",VALUE(LEFT(G1000,FIND(":",G1000)-1)))

Sheet Contour_Lines_Hydro_L
A1: User_Code | B1: KIND_Display | C1: KIND | D1: ALTITUDE | E1: Notes
A2: CONTOUR_LINES_HYDRO_L_001 | C2: =IF(B2="","",VALUE(LEFT(B2,FIND(":",B2)-1)))
C3: =IF(B3="","",VALUE(LEFT(B3,FIND(":",B3)-1)))
C4: =IF(B4="","",VALUE(LEFT(B4,FIND(":",B4)-1)))
C5: =IF(B5="","",VALUE(LEFT(B5,FIND(":",B5)-1)))
C6: =IF(B6="","",VALUE(LEFT(B6,FIND(":",B6)-1)))
C7: =IF(B7="","",VALUE(LEFT(B7,FIND(":",B7)-1)))
C8: =IF(B8="","",VALUE(LEFT(B8,FIND(":",B8)-1)))
C9: =IF(B9="","",VALUE(LEFT(B9,FIND(":",B9)-1)))
C10: =IF(B10="","",VALUE(LEFT(B10,FIND(":",B10)-1)))
C11: =IF(B11="","",VALUE(LEFT(B11,FIND(":",B11)-1)))
C12: =IF(B12="","",VALUE(LEFT(B12,FIND(":",B12)-1)))
C13: =IF(B13="","",VALUE(LEFT(B13,FIND(":",B13)-1)))
C14: =IF(B14="","",VALUE(LEFT(B14,FIND(":",B14)-1)))
... C1000: =IF(B1000="","",VALUE(LEFT(B1000,FIND(":",B1000)-1)))

Sheet Exploitation_Geomaterials_L
A1: User_Code | B1: KIND_Display | C1: KIND | D1: STATUS_Display | E1: STATUS | F1: Notes
A2: EXPLOITATION_GEOMATERIALS_L_001 | C2: =IF(B2="","",VALUE(LEFT(B2,FIND(":",B2)-1))) | E2: =IF(D2="","",VALUE(LEFT(D2,FIND(":",D2)-1)))
C3: =IF(B3="","",VALUE(LEFT(B3,FIND(":",B3)-1))) | E3: =IF(D3="","",VALUE(LEFT(D3,FIND(":",D3)-1)))
C4: =IF(B4="","",VALUE(LEFT(B4,FIND(":",B4)-1))) | E4: =IF(D4="","",VALUE(LEFT(D4,FIND(":",D4)-1)))
C5: =IF(B5="","",VALUE(LEFT(B5,FIND(":",B5)-1))) | E5: =IF(D5="","",VALUE(LEFT(D5,FIND(":",D5)-1)))
C6: =IF(B6="","",VALUE(LEFT(B6,FIND(":",B6)-1))) | E6: =IF(D6="","",VALUE(LEFT(D6,FIND(":",D6)-1)))
C7: =IF(B7="","",VALUE(LEFT(B7,FIND(":",B7)-1))) | E7: =IF(D7="","",VALUE(LEFT(D7,FIND(":",D7)-1)))
C8: =IF(B8="","",VALUE(LEFT(B8,FIND(":",B8)-1))) | E8: =IF(D8="","",VALUE(LEFT(D8,FIND(":",D8)-1)))
C9: =IF(B9="","",VALUE(LEFT(B9,FIND(":",B9)-1))) | E9: =IF(D9="","",VALUE(LEFT(D9,FIND(":",D9)-1)))
C10: =IF(B10="","",VALUE(LEFT(B10,FIND(":",B10)-1))) | E10: =IF(D10="","",VALUE(LEFT(D10,FIND(":",D10)-1)))
C11: =IF(B11="","",VALUE(LEFT(B11,FIND(":",B11)-1))) | E11: =IF(D11="","",VALUE(LEFT(D11,FIND(":",D11)-1)))
C12: =IF(B12="","",VALUE(LEFT(B12,FIND(":",B12)-1))) | E12: =IF(D12="","",VALUE(LEFT(D12,FIND(":",D12)-1)))
C13: =IF(B13="","",VALUE(LEFT(B13,FIND(":",B13)-1))) | E13: =IF(D13="","",VALUE(LEFT(D13,FIND(":",D13)-1)))
C14: =IF(B14="","",VALUE(LEFT(B14,FIND(":",B14)-1))) | E14: =IF(D14="","",VALUE(LEFT(D14,FIND(":",D14)-1)))
... C1000: =IF(B1000="","",VALUE(LEFT(B1000,FIND(":",B1000)-1))) | E1000: =IF(D1000="","",VALUE(LEFT(D1000,FIND(":",D1000)-1)))

Sheet Construction_L
A1: User_Code | B1: KIND_Display | C1: KIND | D1: Notes
A2: CONSTRUCTION_L_001 | C2: =IF(B2="","",VALUE(LEFT(B2,FIND(":",B2)-1)))
C3: =IF(B3="","",VALUE(LEFT(B3,FIND(":",B3)-1)))
C4: =IF(B4="","",VALUE(LEFT(B4,FIND(":",B4)-1)))
C5: =IF(B5="","",VALUE(LEFT(B5,FIND(":",B5)-1)))
C6: =IF(B6="","",VALUE(LEFT(B6,FIND(":",B6)-1)))
C7: =IF(B7="","",VALUE(LEFT(B7,FIND(":",B7)-1)))
C8: =IF(B8="","",VALUE(LEFT(B8,FIND(":",B8)-1)))
C9: =IF(B9="","",VALUE(LEFT(B9,FIND(":",B9)-1)))
C10: =IF(B10="","",VALUE(LEFT(B10,FIND(":",B10)-1)))
C11: =IF(B11="","",VALUE(LEFT(B11,FIND(":",B11)-1)))
C12: =IF(B12="","",VALUE(LEFT(B12,FIND(":",B12)-1)))
C13: =IF(B13="","",VALUE(LEFT(B13,FIND(":",B13)-1)))
C14: =IF(B14="","",VALUE(LEFT(B14,FIND(":",B14)-1)))
... C1000: =IF(B1000="","",VALUE(LEFT(B1000,FIND(":",B1000)-1)))

Sheet Surface_Water_L
A1: User_Code | B1: KIND_Display | C1: KIND | D1: Notes
A2: SURFACE_WATER_L_001 | C2: =IF(B2="","",VALUE(LEFT(B2,FIND(":",B2)-1)))
C3: =IF(B3="","",VALUE(LEFT(B3,FIND(":",B3)-1)))
C4: =IF(B4="","",VALUE(LEFT(B4,FIND(":",B4)-1)))
C5: =IF(B5="","",VALUE(LEFT(B5,FIND(":",B5)-1)))
C6: =IF(B6="","",VALUE(LEFT(B6,FIND(":",B6)-1)))
C7: =IF(B7="","",VALUE(LEFT(B7,FIND(":",B7)-1)))
C8: =IF(B8="","",VALUE(LEFT(B8,FIND(":",B8)-1)))
C9: =IF(B9="","",VALUE(LEFT(B9,FIND(":",B9)-1)))
C10: =IF(B10="","",VALUE(LEFT(B10,FIND(":",B10)-1)))
C11: =IF(B11="","",VALUE(LEFT(B11,FIND(":",B11)-1)))
C12: =IF(B12="","",VALUE(LEFT(B12,FIND(":",B12)-1)))
C13: =IF(B13="","",VALUE(LEFT(B13,FIND(":",B13)-1)))
C14: =IF(B14="","",VALUE(LEFT(B14,FIND(":",B14)-1)))
... C1000: =IF(B1000="","",VALUE(LEFT(B1000,FIND(":",B1000)-1)))

Sheet Subsurface_Water_L
A1: User_Code | B1: KIND_Display | C1: KIND | D1: Notes
A2: SUBSURFACE_WATER_L_001 | C2: =IF(B2="","",VALUE(LEFT(B2,FIND(":",B2)-1)))
C3: =IF(B3="","",VALUE(LEFT(B3,FIND(":",B3)-1)))
C4: =IF(B4="","",VALUE(LEFT(B4,FIND(":",B4)-1)))
C5: =IF(B5="","",VALUE(LEFT(B5,FIND(":",B5)-1)))
C6: =IF(B6="","",VALUE(LEFT(B6,FIND(":",B6)-1)))
C7: =IF(B7="","",VALUE(LEFT(B7,FIND(":",B7)-1)))
C8: =IF(B8="","",VALUE(LEFT(B8,FIND(":",B8)-1)))
C9: =IF(B9="","",VALUE(LEFT(B9,FIND(":",B9)-1)))
C10: =IF(B10="","",VALUE(LEFT(B10,FIND(":",B10)-1)))
C11: =IF(B11="","",VALUE(LEFT(B11,FIND(":",B11)-1)))
C12: =IF(B12="","",VALUE(LEFT(B12,FIND(":",B12)-1)))
C13: =IF(B13="","",VALUE(LEFT(B13,FIND(":",B13)-1)))
C14: =IF(B14="","",VALUE(LEFT(B14,FIND(":",B14)-1)))
... C1000: =IF(B1000="","",VALUE(LEFT(B1000,FIND(":",B1000)-1)))

Sheet Palaeohydrology_L
A1: User_Code | B1: KIND_Display | C1: KIND | D1: REF_YEAR | E1: Notes
A2: PALAEOHYDROLOGY_L_001 | C2: =IF(B2="","",VALUE(LEFT(B2,FIND(":",B2)-1)))
C3: =IF(B3="","",VALUE(LEFT(B3,FIND(":",B3)-1)))
C4: =IF(B4="","",VALUE(LEFT(B4,FIND(":",B4)-1)))
C5: =IF(B5="","",VALUE(LEFT(B5,FIND(":",B5)-1)))
C6: =IF(B6="","",VALUE(LEFT(B6,FIND(":",B6)-1)))
C7: =IF(B7="","",VALUE(LEFT(B7,FIND(":",B7)-1)))
C8: =IF(B8="","",VALUE(LEFT(B8,FIND(":",B8)-1)))
C9: =IF(B9="","",VALUE(LEFT(B9,FIND(":",B9)-1)))
C10: =IF(B10="","",VALUE(LEFT(B10,FIND(":",B10)-1)))
C11: =IF(B11="","",VALUE(LEFT(B11,FIND(":",B11)-1)))
C12: =IF(B12="","",VALUE(LEFT(B12,FIND(":",B12)-1)))
C13: =IF(B13="","",VALUE(LEFT(B13,FIND(":",B13)-1)))
C14: =IF(B14="","",VALUE(LEFT(B14,FIND(":",B14)-1)))
... C1000: =IF(B1000="","",VALUE(LEFT(B1000,FIND(":",B1000)-1)))

Sheet Ref_GeolMappingUnit
A1: Code | B1: Label | C1: Display
A2: 15200001 | B2: Twannbach-Fm. | C2: 15200001: Twannbach-Fm.
A3: 15200002 | B3: Reuchenette-Fm. | C3: 15200002: Reuchenette-Fm.
A4: 15200003 | B4: Courgenay-Fm. | C4: 15200003: Courgenay-Fm.
A5: 15200004 | B5: Vellerat-Fm. | C5: 15200004: Vellerat-Fm.
A6: 15200005 | B6: St-Ursanne-Fm. | C6: 15200005: St-Ursanne-Fm.
A7: 15200006 | B7: Bärschwil-Fm. | C7: 15200006: Bärschwil-Fm.
A8: 15200007 | B8: Ifenthal-Fm. | C8: 15200007: Ifenthal-Fm.
A9: 15200008 | B9: Hauptrogenstein | C9: 15200008: Hauptrogenstein
A10: 15200009 | B10: Passwang-Fm. | C10: 15200009: Passwang-Fm.
A11: 15200010 | B11: Opalinus-Ton | C11: 15200010: Opalinus-Ton
A12: 15200011 | B12: Staffelegg-Fm. | C12: 15200011: Staffelegg-Fm.
A13: 15200012 | B13: Juragebirge: Malm | C13: 15200012: Juragebirge: Malm
... A2976: 15206119 | B2976: Undifferenzierte lithologische Einheit: Basisches Gestein | C2976: 15206119: Undifferenzierte lithologische Einheit: Basisches Gestein

Sheet Ref_Litho
A1: Code | B1: Label | C1: Display
A2: 15101001 | B2: Lockergestein | C2: 15101001: Lockergestein
A3: 15101003 | B3: gravitative Sedimente und Verwitterungsbildungen, undifferenziert | C3: 15101003: gravitative Sedimente und Verwitterungsbildungen, undifferenziert
A4: 15101005 | B4: Sturzablagerung, undifferenziert | C4: 15101005: Sturzablagerung, undifferenziert
A5: 15101006 | B5: Bergsturzablagerung | C5: 15101006: Bergsturzablagerung
A6: 15101007 | B6: Felssturzablagerung | C6: 15101007: Felssturzablagerung
A7: 15101008 | B7: Lawinenschutt | C7: 15101008: Lawinenschutt
A8: 15101009 | B8: Hangschutt | C8: 15101009: Hangschutt
A9: 15101010 | B9: Blockschutt | C9: 15101010: Blockschutt
A10: 15101012 | B10: Verwitterungslehm, undifferenziert | C10: 15101012: Verwitterungslehm, undifferenziert
A11: 15101013 | B11: Plateaulehm | C11: 15101013: Plateaulehm
A12: 15101014 | B12: Hanglehm, Schwemmlehm | C12: 15101014: Hanglehm, Schwemmlehm
A13: 15101015 | B13: Blockgletscher | C13: 15101015: Blockgletscher
... A709: 15111642 | B709: Schiefer: kalkig-kieselig | C709: 15111642: Schiefer: kalkig-kieselig

Sheet Ref_Chrono
A1: Code | B1: Label | C1: Display
A2: 15001001 | B2: Phanerozoikum | C2: 15001001: Phanerozoikum
A3: 15001002 | B3: Känozoikum | C3: 15001002: Känozoikum
A4: 15001003 | B4: Quartär | C4: 15001003: Quartär
A5: 15001004 | B5: Holozän | C5: 15001004: Holozän
A6: 15001005 | B6: Pleistozän | C6: 15001005: Pleistozän
A7: 15001006 | B7: Spätes Pleistozän | C7: 15001006: Spätes Pleistozän
A8: 15001007 | B8: Mittleres Pleistozän | C8: 15001007: Mittleres Pleistozän
A9: 15001009 | B9: Frühes Pleistozän | C9: 15001009: Frühes Pleistozän
A10: 15001010 | B10: Calabrien | C10: 15001010: Calabrien
A11: 15001011 | B11: Gélasien | C11: 15001011: Gélasien
A12: 15001012 | B12: Tertiär | C12: 15001012: Tertiär
A13: 15001013 | B13: Neogen | C13: 15001013: Neogen
... A143: 15001156 | B143: Carixien | C143: 15001156: Carixien

Sheet Ref_Tecto
A1: Code | B1: Label | C1: Display
A2: 15309001 | B2: Autochthones Nordalpines Vorland | C2: 15309001: Autochthones Nordalpines Vorland
A3: 15309002 | B3: Bresse-Graben | C3: 15309002: Bresse-Graben
A4: 15309003 | B4: Haute-Saône-Tafel | C4: 15309003: Haute-Saône-Tafel
A5: 15309004 | B5: Oberrhein-Graben | C5: 15309004: Oberrhein-Graben
A6: 15309005 | B6: Süddeutsche Tafel | C6: 15309005: Süddeutsche Tafel
A7: 15309006 | B7: Hegau-Bodensee-Graben | C7: 15309006: Hegau-Bodensee-Graben
A8: 15309007 | B8: Übergangszone zwischen Abgeschertem und Autochthonem Vorlandplateau | C8: 15309007: Übergangszone zwischen Abgeschertem und Autochthonem Vorlandplateau
A9: 15309008 | B9: Abgeschertes Nordalpines Vorland | C9: 15309008: Abgeschertes Nordalpines Vorland
A10: 15309009 | B10: Externer Faltenjura | C10: 15309009: Externer Faltenjura
A11: 15309010 | B11: Faisceaux | C11: 15309010: Faisceaux
A12: 15309011 | B12: Plateaux | C12: 15309011: Plateaux
A13: 15309012 | B13: Interner Faltenjura und Vorlandplateau | C13: 15309012: Interner Faltenjura und Vorlandplateau
... A407: 15309406 | B407: Ausserberg-Avat-Zone | C407: 15309406: Ausserberg-Avat-Zone

Sheet Ref_LithoStratFormation
A1: Code | B1: Label | C1: Display
A2: 15251001 | B2: Rossemaison-Formation | C2: 15251001: Rossemaison-Formation
A3: 15251002 | B3: Courcelon-Süsswasserkalk | C3: 15251002: Courcelon-Süsswasserkalk
A4: 15251003 | B4: Erzmatt-Krustenkalk | C4: 15251003: Erzmatt-Krustenkalk
A5: 15251004 | B5: Oberdorf-Süsswasserkalk | C5: 15251004: Oberdorf-Süsswasserkalk
A6: 15251005 | B6: Diegten-Süsswasserkalk | C6: 15251005: Diegten-Süsswasserkalk
A7: 15251006 | B7: La-Charrue-Süsswasserkalk | C7: 15251006: La-Charrue-Süsswasserkalk
A8: 15251007 | B8: Champ-Vuillerat-Süsswasserkalk | C8: 15251007: Champ-Vuillerat-Süsswasserkalk
A9: 15251008 | B9: La-Verrerie-Süsswasserkalk | C9: 15251008: La-Verrerie-Süsswasserkalk
A10: 15251009 | B10: «Daubrée-Konglomerat» | C10: 15251009: «Daubrée-Konglomerat»
A11: 15251010 | B11: Narlay-Formation | C11: 15251010: Narlay-Formation
A12: 15251011 | B12: Perte-du-Rhône-Formation | C12: 15251011: Perte-du-Rhône-Formation
A13: 15251012 | B13: Poncin-Member | C13: 15251012: Poncin-Member
... A1534: 15259016 | B1534: San-Fedelino-Granit | C1534: 15259016: San-Fedelino-Granit

Sheet Ref_LithoStratUnco
A1: Code | B1: Label | C1: Display
A2: 15201001 | B2: Ältere Ablagerungen, undifferenziert | C2: 15201001: Ältere Ablagerungen, undifferenziert
A3: 15201002 | B3: Niederterrasse | C3: 15201002: Niederterrasse
A4: 15201003 | B4: Hochterrasse | C4: 15201003: Hochterrasse
A5: 15201004 | B5: Tiefere Deckenschotter | C5: 15201004: Tiefere Deckenschotter
A6: 15201005 | B6: Höhere Deckenschotter | C6: 15201005: Höhere Deckenschotter
A7: 15201006 | B7: Birrfeld-Eiszeit (Letzte Eiszeit) | C7: 15201006: Birrfeld-Eiszeit (Letzte Eiszeit)
A8: 15201007 | B8: Last Glacial Maximum (LGM), undiff. | C8: 15201007: Last Glacial Maximum (LGM), undiff.
A9: 15201008 | B9: LGM-Rückzug | C9: 15201008: LGM-Rückzug
A10: 15201009 | B10: Birmenstorf-Vergletscherung (2. LGM-Vorstoss) | C10: 15201009: Birmenstorf-Vergletscherung (2. LGM-Vorstoss)
A11: 15201010 | B11: Wettingen-Vorstoss | C11: 15201010: Wettingen-Vorstoss
A12: 15201011 | B12: Flüefeld-Schotter | C12: 15201011: Flüefeld-Schotter
A13: 15201012 | B13: Altberg-Till | C13: 15201012: Altberg-Till
... A599: 15201715 | B599: Bellevue-Schotter | C599: 15201715: Bellevue-Schotter

Sheet Ref_System
A1: Code | B1: Label | C1: Display
A2: 12903001 | B2: Vertebraten | C2: 12903001: Vertebraten
A3: 12903002 | B3: Ostrakoden | C3: 12903002: Ostrakoden
A4: 12903003 | B4: Gastropoden | C4: 12903003: Gastropoden
A5: 12903004 | B5: Foraminiferen | C5: 12903004: Foraminiferen
A6: 12903005 | B6: Algen | C6: 12903005: Algen
A7: 12903006 | B7: Blätter | C7: 12903006: Blätter
A8: 12903007 | B8: Gräser | C8: 12903007: Gräser
A9: 12903008 | B9: Holz | C9: 12903008: Holz
A10: 12903009 | B10: Ammoniten | C10: 12903009: Ammoniten
A11: 12903010 | B11: Schwämme | C11: 12903010: Schwämme
A12: 12903011 | B12: Korallen | C12: 12903011: Korallen
A13: 12903012 | B13: Brachiopoden | C13: 12903012: Brachiopoden
... A21: 12903021 | B21: Palynomorphe | C21: 12903021: Palynomorphe

Sheet Ref_GMU_Attributes
A1: GEOL_MAPPING_UNIT | B1: LITSTRAT_FORMATION_BANK | C1: CHRONO_TOP | D1: CHRONO_BASE | E1: LITHO_MAIN | F1: LITHO_SEC | G1: LITHO_TER
A2: 15200255 | B2: 0 | C2: 15001022 | D2: 15001025 | E2: 15111132 | F2: 15111044 | G2: 15111028
A3: 15202389 | B3: 15253162 | C3: 15001078 | D3: 15001078 | E3: 15111123 | F3: 15111056 | G3: 15111074
A4: 15202390 | B4: 15253162 | C4: 15001078 | D4: 15001078 | E4: 15111123 | F4: 15111056 | G4: 15111247
A5: 15202391 | B5: 15253162 | C5: 15001078 | D5: 15001078 | E5: 15111240 | F5: 15111132 | G5: 15111196
A6: 15202392 | B6: 15253204 | C6: 15001113 | D6: 15001113 | E6: 15111565 | F6: 15111561
A7: 15202393 | B7: 15253031 | C7: 15001037 | D7: 15001037 | E7: 15111028
A8: 15202394 | B8: 15253026 | C8: 15001037 | D8: 15001037 | E8: 15111074 | F8: 15111132
A9: 15202395 | B9: 15253069 | C9: 15001056 | D9: 15001056 | E9: 15111229
A10: 15202396 | B10: 15253070 | C10: 15001056 | D10: 15001057 | E10: 15111052
A11: 15202397 | B11: 15253089 | C11: 15001060 | D11: 15001060 | E11: 15111071
A12: 15202398 | B12: 15253109 | C12: 15001063 | D12: 15001063 | E12: 15111197
A13: 15202399 | B13: 15253111 | C13: 15001063 | D13: 15001063 | E13: 15111248 | F13: 15111259
A14: 15202400 | B14: 15253153 | C14: 15001076 | D14: 15001076 | E14: 15111260 | F14: 15111207
A15: 15202401 | B15: 15253358 | C15: 15001076 | D15: 15001077 | E15: 15111592 | F15: 15111265
A16: 15202402 | B16: 15253358 | C16: 15001076 | D16: 15001077 | E16: 15111623 | F16: 15111133
A17: 15202403 | B17: 15253358 | C17: 15001076 | D17: 15001077 | E17: 15111186 | F17: 15111623 | G17: 15111133
A18: 15202404 | B18: 15253157 | C18: 15001077 | D18: 15001077 | E18: 15111209 | F18: 15111259 | G18: 15111247
A19: 15202405 | B19: 15253157 | C19: 15001077 | D19: 15001077 | E19: 15111142 | F19: 15111209 | G19: 15111260
A20: 15202406 | B20: 15253163 | C20: 15001078 | D20: 15001078 | E20: 15111198
A21: 15202407 | B21: 15253272 | C21: 15001126 | D21: 15001126 | E21: 15111391
A22: 15202409 | B22: 15253273 | C22: 15001142 | D22: 15001142 | E22: 15111432 | F22: 15111435 | G22: 15111418
A23: 15202411 | B23: 15253025 | C23: 15001035 | D23: 15001035 | E23: 15111011
A24: 15202412 | B24: 15253121 | C24: 15001064 | D24: 15001064 | E24: 15111168 | F24: 15111229
A25: 15202413 | B25: 15253121 | C25: 15001064 | D25: 15001064 | E25: 15111132 | F25: 15111221
A26: 15202414 | B26: 15253149 | C26: 15001073 | D26: 15001074 | E26: 15111260
A27: 15202415 | B27: 15253148 | C27: 15001073 | D27: 15001074 | E27: 15111123 | F27: 15111175
A28: 15202416 | B28: 15253146 | C28: 15001073 | D28: 15001074 | E28: 15111074 | F28: 15111248 | G28: 15111102
A29: 15202417 | B29: 15253357 | C29: 15001074 | D29: 15001074 | E29: 15111074
A30: 15202418 | B30: 15253171 | C30: 15001084 | D30: 15001087 | E30: 15111297
A31: 15202419 | B31: 15253172 | C31: 15001087 | D31: 15001087 | E31: 15111102 | F31: 15111044 | G31: 15111277
A32: 15202420 | B32: 15253168 | C32: 15001081 | D32: 15001081 | E32: 15111123 | F32: 15111097
A33: 15202421 | B33: 15253064 | C33: 15001053 | D33: 15001054 | E33: 15111132
A34: 15202422 | B34: 15253066 | C34: 15001054 | D34: 15001055 | E34: 15111133
A35: 15202423 | B35: 15253384 | C35: 15001056 | D35: 15001056 | E35: 15111132 | F35: 15111229
A36: 15202424 | B36: 15253385 | C36: 15001059 | D36: 15001060 | E36: 15111189 | F36: 15111250
A37: 15202425 | B37: 15253385 | C37: 15001059 | D37: 15001060 | E37: 15111132
A38: 15202426 | B38: 15253385 | C38: 15001060 | D38: 15001060 | E38: 15111250 | F38: 15111171
A39: 15202427 | B39: 15253386 | C39: 15001061 | D39: 15001061 | E39: 15111190
A40: 15202429 | B40: 15253387 | C40: 15001060 | D40: 15001064 | E40: 15111229 | F40: 15111132
...

Sheet Ref_FossilDivision
A1: Code | B1: Label | C1: Display
A2: 999997 | B2: Unknown | C2: 999997: Unknown
A3: 999998 | B3: Not applicable | C3: 999998: Not applicable
A4: 12902001 | B4: Tierreste | C4: 12902001: Tierreste
A5: 12902002 | B5: Pflanzen- und Tierreste | C5: 12902002: Pflanzen- und Tierreste
A6: 12902003 | B6: Pflanzenreste | C6: 12902003: Pflanzenreste
A7: 12902004 | B7: Spuren | C7: 12902004: Spuren
A8: 12902006 | B8: Einzeller | C8: 12902006: Einzeller

Sheet Ref_TectoStatus
A1: Code | B1: Label | C1: Display
A2: 999997 | B2: Unknown | C2: 999997: Unknown
A3: 999998 | B3: Not applicable | C3: 999998: Not applicable
A4: 14906001 | B4: gesichert, im Allgemeinen | C4: 14906001: gesichert, im Allgemeinen
A5: 14906002 | B5: gesichert, unter Tage festgestellt | C5: 14906002: gesichert, unter Tage festgestellt
A6: 14906003 | B6: vermutet | C6: 14906003: vermutet
A7: 14906004 | B7: aus Seismikdaten interpretiert | C7: 14906004: aus Seismikdaten interpretiert

Sheet Ref_TectoLimTyp
A1: Code | B1: Label | C1: Display
A2: 999997 | B2: Unknown | C2: 999997: Unknown
A3: 999998 | B3: Not applicable | C3: 999998: Not applicable
A4: 14910001 | B4: Decken trennend | C4: 14910001: Decken trennend
A5: 14910002 | B5: Schuppen trennend | C5: 14910002: Schuppen trennend

Sheet Ref_TectoHiera
A1: Code | B1: Label | C1: Display
A2: 999997 | B2: Unknown | C2: 999997: Unknown
A3: 999998 | B3: Not applicable | C3: 999998: Not applicable
A4: 14911001 | B4: Störung | C4: 14911001: Störung
A5: 14911002 | B5: Teilstörungssystem | C5: 14911002: Teilstörungssystem
A6: 14911003 | B6: Grossstörungssystem | C6: 14911003: Grossstörungssystem

Sheet Ref_ContourBedrockType
A1: Code | B1: Label | C1: Display
A2: 999997 | B2: Unknown | C2: 999997: Unknown
A3: 999998 | B3: Not applicable | C3: 999998: Not applicable
A4: 13902001 | B4: Felsoberfläche | C4: 13902001: Felsoberfläche
A5: 13902002 | B5: Obergrenze einer gegebenen Formation | C5: 13902002: Obergrenze einer gegebenen Formation
A6: 13902003 | B6: Untergrenze einer gegebenen Formation | C6: 13902003: Untergrenze einer gegebenen Formation
